<?xml version="1.0" encoding="UTF-8"?>
<testng-results skipped="0" failed="1" total="3" passed="2">
  <reporter-output>
  </reporter-output>
  <suite name="Default suite" duration-ms="26239" started-at="2017-12-10T17:29:25Z" finished-at="2017-12-10T17:29:51Z">
    <groups>
    </groups>
    <test name="Default test" duration-ms="26239" started-at="2017-12-10T17:29:25Z" finished-at="2017-12-10T17:29:51Z">
      <class name="tests.tryCatch_assertion">
        <test-method status="PASS" signature="beforeClass()[pri:0, instance:tests.tryCatch_assertion@4439f31e]" name="beforeClass" is-config="true" duration-ms="6850" started-at="2017-12-10T12:29:25Z" finished-at="2017-12-10T12:29:31Z">
          <reporter-output>
          </reporter-output>
        </test-method> <!-- beforeClass -->
        <test-method status="FAIL" signature="assertRightThere()[pri:0, instance:tests.tryCatch_assertion@4439f31e]" name="assertRightThere" duration-ms="24" started-at="2017-12-10T12:29:31Z" finished-at="2017-12-10T12:29:31Z">
          <exception class="java.lang.AssertionError">
            <message>
              <![CDATA[expected [a] but found [b]]]>
            </message>
            <full-stacktrace>
              <![CDATA[java.lang.AssertionError: expected [a] but found [b]
	at org.testng.Assert.fail(Assert.java:94)
	at org.testng.Assert.failNotEquals(Assert.java:513)
	at org.testng.Assert.assertEqualsImpl(Assert.java:135)
	at org.testng.Assert.assertEquals(Assert.java:116)
	at org.testng.Assert.assertEquals(Assert.java:190)
	at org.testng.Assert.assertEquals(Assert.java:200)
	at tests.tryCatch_assertion.assertRightThere(tryCatch_assertion.java:45)
	at sun.reflect.NativeMethodAccessorImpl.invoke0(Native Method)
	at sun.reflect.NativeMethodAccessorImpl.invoke(Unknown Source)
	at sun.reflect.DelegatingMethodAccessorImpl.invoke(Unknown Source)
	at java.lang.reflect.Method.invoke(Unknown Source)
	at org.testng.internal.MethodInvocationHelper.invokeMethod(MethodInvocationHelper.java:86)
	at org.testng.internal.Invoker.invokeMethod(Invoker.java:646)
	at org.testng.internal.Invoker.invokeTestMethod(Invoker.java:823)
	at org.testng.internal.Invoker.invokeTestMethods(Invoker.java:1131)
	at org.testng.internal.TestMethodWorker.invokeTestMethods(TestMethodWorker.java:129)
	at org.testng.internal.TestMethodWorker.run(TestMethodWorker.java:112)
	at org.testng.TestRunner.privateRun(TestRunner.java:778)
	at org.testng.TestRunner.run(TestRunner.java:632)
	at org.testng.SuiteRunner.runTest(SuiteRunner.java:366)
	at org.testng.SuiteRunner.runSequentially(SuiteRunner.java:361)
	at org.testng.SuiteRunner.privateRun(SuiteRunner.java:319)
	at org.testng.SuiteRunner.run(SuiteRunner.java:268)
	at org.testng.SuiteRunnerWorker.runSuite(SuiteRunnerWorker.java:52)
	at org.testng.SuiteRunnerWorker.run(SuiteRunnerWorker.java:86)
	at org.testng.TestNG.runSuitesSequentially(TestNG.java:1225)
	at org.testng.TestNG.runSuitesLocally(TestNG.java:1150)
	at org.testng.TestNG.runSuites(TestNG.java:1075)
	at org.testng.TestNG.run(TestNG.java:1047)
	at org.testng.remote.AbstractRemoteTestNG.run(AbstractRemoteTestNG.java:126)
	at org.testng.remote.RemoteTestNG.initAndRun(RemoteTestNG.java:137)
	at org.testng.remote.RemoteTestNG.main(RemoteTestNG.java:58)
]]>
            </full-stacktrace>
          </exception> <!-- java.lang.AssertionError -->
          <reporter-output>
          </reporter-output>
        </test-method> <!-- assertRightThere -->
        <test-method status="PASS" signature="afterMethod()[pri:0, instance:tests.tryCatch_assertion@4439f31e]" name="afterMethod" is-config="true" duration-ms="2740" started-at="2017-12-10T12:29:31Z" finished-at="2017-12-10T12:29:34Z">
          <reporter-output>
          </reporter-output>
        </test-method> <!-- afterMethod -->
        <test-method status="PASS" signature="beforeClass()[pri:0, instance:tests.tryCatch_assertion@4439f31e]" name="beforeClass" is-config="true" duration-ms="5134" started-at="2017-12-10T12:29:34Z" finished-at="2017-12-10T12:29:39Z">
          <reporter-output>
          </reporter-output>
        </test-method> <!-- beforeClass -->
        <test-method status="PASS" signature="learnAssertion()[pri:0, instance:tests.tryCatch_assertion@4439f31e]" name="learnAssertion" duration-ms="81" started-at="2017-12-10T12:29:39Z" finished-at="2017-12-10T12:29:39Z">
          <reporter-output>
          </reporter-output>
        </test-method> <!-- learnAssertion -->
        <test-method status="PASS" signature="afterMethod()[pri:0, instance:tests.tryCatch_assertion@4439f31e]" name="afterMethod" is-config="true" duration-ms="2724" started-at="2017-12-10T12:29:39Z" finished-at="2017-12-10T12:29:42Z">
          <reporter-output>
          </reporter-output>
        </test-method> <!-- afterMethod -->
        <test-method status="PASS" signature="beforeClass()[pri:0, instance:tests.tryCatch_assertion@4439f31e]" name="beforeClass" is-config="true" duration-ms="7761" started-at="2017-12-10T12:29:42Z" finished-at="2017-12-10T12:29:50Z">
          <reporter-output>
          </reporter-output>
        </test-method> <!-- beforeClass -->
        <test-method status="PASS" signature="tryCatchTesting()[pri:0, instance:tests.tryCatch_assertion@4439f31e]" name="tryCatchTesting" duration-ms="5" started-at="2017-12-10T12:29:50Z" finished-at="2017-12-10T12:29:50Z">
          <reporter-output>
          </reporter-output>
        </test-method> <!-- tryCatchTesting -->
        <test-method status="PASS" signature="afterMethod()[pri:0, instance:tests.tryCatch_assertion@4439f31e]" name="afterMethod" is-config="true" duration-ms="873" started-at="2017-12-10T12:29:50Z" finished-at="2017-12-10T12:29:51Z">
          <reporter-output>
          </reporter-output>
        </test-method> <!-- afterMethod -->
      </class> <!-- tests.tryCatch_assertion -->
    </test> <!-- Default test -->
  </suite> <!-- Default suite -->
</testng-results>
